Workbook

Sheet Start Here
C2: Sorted. Budget Planner
C3: Ten minutes a week. Every pound, dollar or euro with a job.
C5: How to use it
B6: 1 | C6: Setup tab: Type your budget year, your income sources and what you plan to spend per category each month. Rename or add categories freely (up to 30).
B7: 2 | C7: Transactions tab: Log each payment and paycheck: date, description, pick a category from the dropdown, amount. The example rows are there to show the format: delete them when you start.
B8: 3 | C8: This Month tab: Pick a month from the dropdown. See budget vs actual for every category, what's left, and your Needs / Wants / Savings split against 50/30/20.
B9: 4 | C9: Year Dashboard tab: Twelve months at a glance with charts: income, spending by group, savings rate.
B10: 5 | C10: Debt Payoff tab: List your debts in the order you want to clear them, add any extra monthly payment, and see your debt-free date and total interest.
B11: 6 | C11: Savings Goals tab: Set targets and dates. Sorted tells you how much to put aside each month.
C13: Colour key
C14: Yellow cells are yours to type in. Everything else calculates itself, so you can't break it.
C16: Works in
C17: Microsoft Excel (2010 or newer, Windows and Mac), Google Sheets (File > Import > Upload) and Apple Numbers.
C18: Amounts have no currency symbol, so the planner works in any currency.
C20: Tip: back up a blank copy before you start, so you can reuse it next year.

Sheet Setup
B2: Setup
B3: Set this once. Change it whenever life changes.
B5: Budget year | C5: 2027
B7: Category | C7: Group | D7: Monthly budget | F7: Your plan in one look
B8: Salary | C8: Income | D8: 4200 | F8: Planned income | G8: =SUMIFS($D$8:$D$37,$C$8:$C$37,"Income") -> 4600
B9: Side income | C9: Income | D9: 400 | F9: Planned needs | G9: =SUMIFS($D$8:$D$37,$C$8:$C$37,"Needs") -> 2510
B10: Rent / mortgage | C10: Needs | D10: 1350 | F10: Planned wants | G10: =SUMIFS($D$8:$D$37,$C$8:$C$37,"Wants") -> 645
B11: Utilities | C11: Needs | D11: 180 | F11: Planned savings | G11: =SUMIFS($D$8:$D$37,$C$8:$C$37,"Savings") -> 1045
B12: Groceries | C12: Needs | D12: 450 | F12: Planned debt | G12: =SUMIFS($D$8:$D$37,$C$8:$C$37,"Debt") -> 400
B13: Transport | C13: Needs | D13: 220 | F13: Left to assign | G13: =G8-SUM(G9:G12) -> 0
B14: Insurance | C14: Needs | D14: 160 | F14: Aim for 0: every unit of income gets a job (zero-based budgeting).
B15: Phone & internet | C15: Needs | D15: 90
B16: Health | C16: Needs | D16: 60
B17: Eating out | C17: Wants | D17: 200
B18: Shopping | C18: Wants | D18: 150
B19: Entertainment | C19: Wants | D19: 80
B20: Subscriptions | C20: Wants | D20: 45
B21: Travel | C21: Wants | D21: 120
B22: Gifts | C22: Wants | D22: 50
B23: Emergency fund | C23: Savings | D23: 500
B24: Investing | C24: Savings | D24: 445
B25: Holiday fund | C25: Savings | D25: 100
B26: Credit card | C26: Debt | D26: 250
B27: Student loan | C27: Debt | D27: 150

Sheet Transactions
B2: Transactions
B3: Log money in and money out. Pick categories from the dropdown. The grey columns fill themselves.
B4: Date | C4: Description | D4: Category | E4: Amount | F4: Group | G4: Month | H4: Year
B5: 46388 | C5: Monthly salary | D5: Salary | E5: 4200 | F5: =IF(D5="","",IFERROR(INDEX(Setup!$C$8:$C$37,MATCH(D5,Setup!$B$8:$B$37,0)),"Check category")) -> Income | G5: =IF(B5="","",MONTH(B5)) -> 1 | H5: =IF(B5="","",YEAR(B5)) -> 2027
B6: 46388 | C6: Rent | D6: Rent / mortgage | E6: 1350 | F6: =IF(D6="","",IFERROR(INDEX(Setup!$C$8:$C$37,MATCH(D6,Setup!$B$8:$B$37,0)),"Check category")) -> Needs | G6: =IF(B6="","",MONTH(B6)) -> 1 | H6: =IF(B6="","",YEAR(B6)) -> 2027
B7: 46389 | C7: Emergency fund transfer | D7: Emergency fund | E7: 500 | F7: =IF(D7="","",IFERROR(INDEX(Setup!$C$8:$C$37,MATCH(D7,Setup!$B$8:$B$37,0)),"Check category")) -> Savings | G7: =IF(B7="","",MONTH(B7)) -> 1 | H7: =IF(B7="","",YEAR(B7)) -> 2027
B8: 46389 | C8: Index fund | D8: Investing | E8: 445 | F8: =IF(D8="","",IFERROR(INDEX(Setup!$C$8:$C$37,MATCH(D8,Setup!$B$8:$B$37,0)),"Check category")) -> Savings | G8: =IF(B8="","",MONTH(B8)) -> 1 | H8: =IF(B8="","",YEAR(B8)) -> 2027
B9: 46390 | C9: Electric & water | D9: Utilities | E9: 178.77 | F9: =IF(D9="","",IFERROR(INDEX(Setup!$C$8:$C$37,MATCH(D9,Setup!$B$8:$B$37,0)),"Check category")) -> Needs | G9: =IF(B9="","",MONTH(B9)) -> 1 | H9: =IF(B9="","",YEAR(B9)) -> 2027
B10: 46391 | C10: Weekly shop | D10: Groceries | E10: 95.88 | F10: =IF(D10="","",IFERROR(INDEX(Setup!$C$8:$C$37,MATCH(D10,Setup!$B$8:$B$37,0)),"Check category")) -> Needs | G10: =IF(B10="","",MONTH(B10)) -> 1 | H10: =IF(B10="","",YEAR(B10)) -> 2027
B11: 46392 | C11: Train pass | D11: Transport | E11: 180 | F11: =IF(D11="","",IFERROR(INDEX(Setup!$C$8:$C$37,MATCH(D11,Setup!$B$8:$B$37,0)),"Check category")) -> Needs | G11: =IF(B11="","",MONTH(B11)) -> 1 | H11: =IF(B11="","",YEAR(B11)) -> 2027
B12: 46393 | C12: Streaming + music | D12: Subscriptions | E12: 45 | F12: =IF(D12="","",IFERROR(INDEX(Setup!$C$8:$C$37,MATCH(D12,Setup!$B$8:$B$37,0)),"Check category")) -> Wants | G12: =IF(B12="","",MONTH(B12)) -> 1 | H12: =IF(B12="","",YEAR(B12)) -> 2027
B13: 46395 | C13: Dinner with friends | D13: Eating out | E13: 52.38 | F13: =IF(D13="","",IFERROR(INDEX(Setup!$C$8:$C$37,MATCH(D13,Setup!$B$8:$B$37,0)),"Check category")) -> Wants | G13: =IF(B13="","",MONTH(B13)) -> 1 | H13: =IF(B13="","",YEAR(B13)) -> 2027
B14: 46398 | C14: Weekly shop | D14: Groceries | E14: 102.81 | F14: =IF(D14="","",IFERROR(INDEX(Setup!$C$8:$C$37,MATCH(D14,Setup!$B$8:$B$37,0)),"Check category")) -> Needs | G14: =IF(B14="","",MONTH(B14)) -> 1 | H14: =IF(B14="","",YEAR(B14)) -> 2027
B15: 46399 | C15: Phone + broadband | D15: Phone & internet | E15: 90 | F15: =IF(D15="","",IFERROR(INDEX(Setup!$C$8:$C$37,MATCH(D15,Setup!$B$8:$B$37,0)),"Check category")) -> Needs | G15: =IF(B15="","",MONTH(B15)) -> 1 | H15: =IF(B15="","",YEAR(B15)) -> 2027
B16: 46401 | C16: Freelance logo job | D16: Side income | E16: 350 | F16: =IF(D16="","",IFERROR(INDEX(Setup!$C$8:$C$37,MATCH(D16,Setup!$B$8:$B$37,0)),"Check category")) -> Income | G16: =IF(B16="","",MONTH(B16)) -> 1 | H16: =IF(B16="","",YEAR(B16)) -> 2027
... B70: 46474 | C70: Flights deposit | D70: Travel | E70: 210 | F70: =IF(D70="","",IFERROR(INDEX(Setup!$C$8:$C$37,MATCH(D70,Setup!$B$8:$B$37,0)),"Check category")) -> Wants | G70: =IF(B70="","",MONTH(B70)) -> 3 | H70: =IF(B70="","",YEAR(B70)) -> 2027
F71: =IF(D71="","",IFERROR(INDEX(Setup!$C$8:$C$37,MATCH(D71,Setup!$B$8:$B$37,0)),"Check category")) | G71: =IF(B71="","",MONTH(B71)) | H71: =IF(B71="","",YEAR(B71))
F72: =IF(D72="","",IFERROR(INDEX(Setup!$C$8:$C$37,MATCH(D72,Setup!$B$8:$B$37,0)),"Check category")) | G72: =IF(B72="","",MONTH(B72)) | H72: =IF(B72="","",YEAR(B72))
F73: =IF(D73="","",IFERROR(INDEX(Setup!$C$8:$C$37,MATCH(D73,Setup!$B$8:$B$37,0)),"Check category")) | G73: =IF(B73="","",MONTH(B73)) | H73: =IF(B73="","",YEAR(B73))
F74: =IF(D74="","",IFERROR(INDEX(Setup!$C$8:$C$37,MATCH(D74,Setup!$B$8:$B$37,0)),"Check category")) | G74: =IF(B74="","",MONTH(B74)) | H74: =IF(B74="","",YEAR(B74))
F75: =IF(D75="","",IFERROR(INDEX(Setup!$C$8:$C$37,MATCH(D75,Setup!$B$8:$B$37,0)),"Check category")) | G75: =IF(B75="","",MONTH(B75)) | H75: =IF(B75="","",YEAR(B75))
F76: =IF(D76="","",IFERROR(INDEX(Setup!$C$8:$C$37,MATCH(D76,Setup!$B$8:$B$37,0)),"Check category")) | G76: =IF(B76="","",MONTH(B76)) | H76: =IF(B76="","",YEAR(B76))
F77: =IF(D77="","",IFERROR(INDEX(Setup!$C$8:$C$37,MATCH(D77,Setup!$B$8:$B$37,0)),"Check category")) | G77: =IF(B77="","",MONTH(B77)) | H77: =IF(B77="","",YEAR(B77))
F78: =IF(D78="","",IFERROR(INDEX(Setup!$C$8:$C$37,MATCH(D78,Setup!$B$8:$B$37,0)),"Check category")) | G78: =IF(B78="","",MONTH(B78)) | H78: =IF(B78="","",YEAR(B78))
F79: =IF(D79="","",IFERROR(INDEX(Setup!$C$8:$C$37,MATCH(D79,Setup!$B$8:$B$37,0)),"Check category")) | G79: =IF(B79="","",MONTH(B79)) | H79: =IF(B79="","",YEAR(B79))
F80: =IF(D80="","",IFERROR(INDEX(Setup!$C$8:$C$37,MATCH(D80,Setup!$B$8:$B$37,0)),"Check category")) | G80: =IF(B80="","",MONTH(B80)) | H80: =IF(B80="","",YEAR(B80))
F81: =IF(D81="","",IFERROR(INDEX(Setup!$C$8:$C$37,MATCH(D81,Setup!$B$8:$B$37,0)),"Check category")) | G81: =IF(B81="","",MONTH(B81)) | H81: =IF(B81="","",YEAR(B81))
F82: =IF(D82="","",IFERROR(INDEX(Setup!$C$8:$C$37,MATCH(D82,Setup!$B$8:$B$37,0)),"Check category")) | G82: =IF(B82="","",MONTH(B82)) | H82: =IF(B82="","",YEAR(B82))
... F1504: =IF(D1504="","",IFERROR(INDEX(Setup!$C$8:$C$37,MATCH(D1504,Setup!$B$8:$B$37,0)),"Check category")) | G1504: =IF(B1504="","",MONTH(B1504)) | H1504: =IF(B1504="","",YEAR(B1504))

Sheet This Month
B2: This Month
B3: Pick a month. Everything below updates.
B5: Month | C5: January | E5: =MATCH(C5,{"January","February","March","April","May","June","July","August","September","October","November","December"},0) -> 1 | F5: =Setup!C5 -> 2027
B7: Category | C7: Group | D7: Budget | E7: Actual | F7: Left | G7: Used | I7: Summary
B8: =IF(Setup!B8="","",Setup!B8) -> Salary | C8: =IF(Setup!B8="","",Setup!C8) -> Income | D8: =IF(B8="","",Setup!D8) -> 4200 | E8: =IF(B8="","",SUMIFS(Transactions!$E$5:$E$1504,Transactions!$D$5:$D$1504,B8,Transactions!$G$5:$G$1504,$E$5,Transactions!$H$5:$H$1504,$F$5)) -> 4200 | F8: =IF(B8="","",IF(C8="Income",E8-D8,D8-E8)) -> 0 | G8: =IF(OR(B8="",N(D8)=0),"",E8/D8) -> 1 | I8: Income received | J8: =SUMIFS(Transactions!$E$5:$E$1504,Transactions!$F$5:$F$1504,"Income",Transactions!$G$5:$G$1504,$E$5,Transactions!$H$5:$H$1504,$F$5) -> 4550
B9: =IF(Setup!B9="","",Setup!B9) -> Side income | C9: =IF(Setup!B9="","",Setup!C9) -> Income | D9: =IF(B9="","",Setup!D9) -> 400 | E9: =IF(B9="","",SUMIFS(Transactions!$E$5:$E$1504,Transactions!$D$5:$D$1504,B9,Transactions!$G$5:$G$1504,$E$5,Transactions!$H$5:$H$1504,$F$5)) -> 350 | F9: =IF(B9="","",IF(C9="Income",E9-D9,D9-E9)) -> -50 | G9: =IF(OR(B9="",N(D9)=0),"",E9/D9) -> 0.875 | I9: Spent (needs + wants) | J9: =SUMIFS(Transactions!$E$5:$E$1504,Transactions!$F$5:$F$1504,"Needs",Transactions!$G$5:$G$1504,$E$5,Transactions!$H$5:$H$1504,$F$5)+SUMIFS(Transactions!$E$5:$E$1504,Transactions!$F$5:$F$1504,"Wants",Transactions!$G$5:$G$1504,$E$5,Transactions!$H$5:$H$1504,$F$5) -> 2761.46
B10: =IF(Setup!B10="","",Setup!B10) -> Rent / mortgage | C10: =IF(Setup!B10="","",Setup!C10) -> Needs | D10: =IF(B10="","",Setup!D10) -> 1350 | E10: =IF(B10="","",SUMIFS(Transactions!$E$5:$E$1504,Transactions!$D$5:$D$1504,B10,Transactions!$G$5:$G$1504,$E$5,Transactions!$H$5:$H$1504,$F$5)) -> 1350 | F10: =IF(B10="","",IF(C10="Income",E10-D10,D10-E10)) -> 0 | G10: =IF(OR(B10="",N(D10)=0),"",E10/D10) -> 1 | I10: Saved | J10: =SUMIFS(Transactions!$E$5:$E$1504,Transactions!$F$5:$F$1504,"Savings",Transactions!$G$5:$G$1504,$E$5,Transactions!$H$5:$H$1504,$F$5) -> 945
B11: =IF(Setup!B11="","",Setup!B11) -> Utilities | C11: =IF(Setup!B11="","",Setup!C11) -> Needs | D11: =IF(B11="","",Setup!D11) -> 180 | E11: =IF(B11="","",SUMIFS(Transactions!$E$5:$E$1504,Transactions!$D$5:$D$1504,B11,Transactions!$G$5:$G$1504,$E$5,Transactions!$H$5:$H$1504,$F$5)) -> 178.77 | F11: =IF(B11="","",IF(C11="Income",E11-D11,D11-E11)) -> 1.23 | G11: =IF(OR(B11="",N(D11)=0),"",E11/D11) -> 0.99316667 | I11: Debt paid | J11: =SUMIFS(Transactions!$E$5:$E$1504,Transactions!$F$5:$F$1504,"Debt",Transactions!$G$5:$G$1504,$E$5,Transactions!$H$5:$H$1504,$F$5) -> 400
B12: =IF(Setup!B12="","",Setup!B12) -> Groceries | C12: =IF(Setup!B12="","",Setup!C12) -> Needs | D12: =IF(B12="","",Setup!D12) -> 450 | E12: =IF(B12="","",SUMIFS(Transactions!$E$5:$E$1504,Transactions!$D$5:$D$1504,B12,Transactions!$G$5:$G$1504,$E$5,Transactions!$H$5:$H$1504,$F$5)) -> 427.14 | F12: =IF(B12="","",IF(C12="Income",E12-D12,D12-E12)) -> 22.86 | G12: =IF(OR(B12="",N(D12)=0),"",E12/D12) -> 0.9492 | I12: Left over | J12: =J8-J9-J10-J11 -> 443.54
B13: =IF(Setup!B13="","",Setup!B13) -> Transport | C13: =IF(Setup!B13="","",Setup!C13) -> Needs | D13: =IF(B13="","",Setup!D13) -> 220 | E13: =IF(B13="","",SUMIFS(Transactions!$E$5:$E$1504,Transactions!$D$5:$D$1504,B13,Transactions!$G$5:$G$1504,$E$5,Transactions!$H$5:$H$1504,$F$5)) -> 215.74 | F13: =IF(B13="","",IF(C13="Income",E13-D13,D13-E13)) -> 4.26 | G13: =IF(OR(B13="",N(D13)=0),"",E13/D13) -> 0.98063636
B14: =IF(Setup!B14="","",Setup!B14) -> Insurance | C14: =IF(Setup!B14="","",Setup!C14) -> Needs | D14: =IF(B14="","",Setup!D14) -> 160 | E14: =IF(B14="","",SUMIFS(Transactions!$E$5:$E$1504,Transactions!$D$5:$D$1504,B14,Transactions!$G$5:$G$1504,$E$5,Transactions!$H$5:$H$1504,$F$5)) -> 160 | F14: =IF(B14="","",IF(C14="Income",E14-D14,D14-E14)) -> 0 | G14: =IF(OR(B14="",N(D14)=0),"",E14/D14) -> 1
B15: =IF(Setup!B15="","",Setup!B15) -> Phone & internet | C15: =IF(Setup!B15="","",Setup!C15) -> Needs | D15: =IF(B15="","",Setup!D15) -> 90 | E15: =IF(B15="","",SUMIFS(Transactions!$E$5:$E$1504,Transactions!$D$5:$D$1504,B15,Transactions!$G$5:$G$1504,$E$5,Transactions!$H$5:$H$1504,$F$5)) -> 90 | F15: =IF(B15="","",IF(C15="Income",E15-D15,D15-E15)) -> 0 | G15: =IF(OR(B15="",N(D15)=0),"",E15/D15) -> 1 | I15: 50 / 30 / 20 check
B16: =IF(Setup!B16="","",Setup!B16) -> Health | C16: =IF(Setup!B16="","",Setup!C16) -> Needs | D16: =IF(B16="","",Setup!D16) -> 60 | E16: =IF(B16="","",SUMIFS(Transactions!$E$5:$E$1504,Transactions!$D$5:$D$1504,B16,Transactions!$G$5:$G$1504,$E$5,Transactions!$H$5:$H$1504,$F$5)) -> 0 | F16: =IF(B16="","",IF(C16="Income",E16-D16,D16-E16)) -> 60 | G16: =IF(OR(B16="",N(D16)=0),"",E16/D16) -> 0 | I16: Group | J16: % of income | K16: Target
B17: =IF(Setup!B17="","",Setup!B17) -> Eating out | C17: =IF(Setup!B17="","",Setup!C17) -> Wants | D17: =IF(B17="","",Setup!D17) -> 200 | E17: =IF(B17="","",SUMIFS(Transactions!$E$5:$E$1504,Transactions!$D$5:$D$1504,B17,Transactions!$G$5:$G$1504,$E$5,Transactions!$H$5:$H$1504,$F$5)) -> 80.42 | F17: =IF(B17="","",IF(C17="Income",E17-D17,D17-E17)) -> 119.58 | G17: =IF(OR(B17="",N(D17)=0),"",E17/D17) -> 0.4021 | I17: Needs | J17: =IFERROR((SUMIFS(Transactions!$E$5:$E$1504,Transactions!$F$5:$F$1504,"Needs",Transactions!$G$5:$G$1504,$E$5,Transactions!$H$5:$H$1504,$F$5))/$J$8,0) -> 0.53223077 | K17: 0.5
B18: =IF(Setup!B18="","",Setup!B18) -> Shopping | C18: =IF(Setup!B18="","",Setup!C18) -> Wants | D18: =IF(B18="","",Setup!D18) -> 150 | E18: =IF(B18="","",SUMIFS(Transactions!$E$5:$E$1504,Transactions!$D$5:$D$1504,B18,Transactions!$G$5:$G$1504,$E$5,Transactions!$H$5:$H$1504,$F$5)) -> 175.98 | F18: =IF(B18="","",IF(C18="Income",E18-D18,D18-E18)) -> -25.98 | G18: =IF(OR(B18="",N(D18)=0),"",E18/D18) -> 1.1732 | I18: Wants | J18: =IFERROR((SUMIFS(Transactions!$E$5:$E$1504,Transactions!$F$5:$F$1504,"Wants",Transactions!$G$5:$G$1504,$E$5,Transactions!$H$5:$H$1504,$F$5))/$J$8,0) -> 0.074683516 | K18: 0.3
B19: =IF(Setup!B19="","",Setup!B19) -> Entertainment | C19: =IF(Setup!B19="","",Setup!C19) -> Wants | D19: =IF(B19="","",Setup!D19) -> 80 | E19: =IF(B19="","",SUMIFS(Transactions!$E$5:$E$1504,Transactions!$D$5:$D$1504,B19,Transactions!$G$5:$G$1504,$E$5,Transactions!$H$5:$H$1504,$F$5)) -> 38.41 | F19: =IF(B19="","",IF(C19="Income",E19-D19,D19-E19)) -> 41.59 | G19: =IF(OR(B19="",N(D19)=0),"",E19/D19) -> 0.480125 | I19: Savings | J19: =IFERROR((SUMIFS(Transactions!$E$5:$E$1504,Transactions!$F$5:$F$1504,"Savings",Transactions!$G$5:$G$1504,$E$5,Transactions!$H$5:$H$1504,$F$5)+SUMIFS(Transactions!$E$5:$E$1504,Transactions!$F$5:$F$1504,"Debt",Transactions!$G$5:$G$1504,$E$5,Transactions!$H$5:$H$1504,$F$5))/$J$8,0) -> 0.2956044 | K19: 0.2
B20: =IF(Setup!B20="","",Setup!B20) -> Subscriptions | C20: =IF(Setup!B20="","",Setup!C20) -> Wants | D20: =IF(B20="","",Setup!D20) -> 45 | E20: =IF(B20="","",SUMIFS(Transactions!$E$5:$E$1504,Transactions!$D$5:$D$1504,B20,Transactions!$G$5:$G$1504,$E$5,Transactions!$H$5:$H$1504,$F$5)) -> 45 | F20: =IF(B20="","",IF(C20="Income",E20-D20,D20-E20)) -> 0 | G20: =IF(OR(B20="",N(D20)=0),"",E20/D20) -> 1 | I20: Savings includes debt paid down, as in the classic 50/30/20 rule.
B21: =IF(Setup!B21="","",Setup!B21) -> Travel | C21: =IF(Setup!B21="","",Setup!C21) -> Wants | D21: =IF(B21="","",Setup!D21) -> 120 | E21: =IF(B21="","",SUMIFS(Transactions!$E$5:$E$1504,Transactions!$D$5:$D$1504,B21,Transactions!$G$5:$G$1504,$E$5,Transactions!$H$5:$H$1504,$F$5)) -> 0 | F21: =IF(B21="","",IF(C21="Income",E21-D21,D21-E21)) -> 120 | G21: =IF(OR(B21="",N(D21)=0),"",E21/D21) -> 0
B22: =IF(Setup!B22="","",Setup!B22) -> Gifts | C22: =IF(Setup!B22="","",Setup!C22) -> Wants | D22: =IF(B22="","",Setup!D22) -> 50 | E22: =IF(B22="","",SUMIFS(Transactions!$E$5:$E$1504,Transactions!$D$5:$D$1504,B22,Transactions!$G$5:$G$1504,$E$5,Transactions!$H$5:$H$1504,$F$5)) -> 0 | F22: =IF(B22="","",IF(C22="Income",E22-D22,D22-E22)) -> 50 | G22: =IF(OR(B22="",N(D22)=0),"",E22/D22) -> 0
B23: =IF(Setup!B23="","",Setup!B23) -> Emergency fund | C23: =IF(Setup!B23="","",Setup!C23) -> Savings | D23: =IF(B23="","",Setup!D23) -> 500 | E23: =IF(B23="","",SUMIFS(Transactions!$E$5:$E$1504,Transactions!$D$5:$D$1504,B23,Transactions!$G$5:$G$1504,$E$5,Transactions!$H$5:$H$1504,$F$5)) -> 500 | F23: =IF(B23="","",IF(C23="Income",E23-D23,D23-E23)) -> 0 | G23: =IF(OR(B23="",N(D23)=0),"",E23/D23) -> 1
B24: =IF(Setup!B24="","",Setup!B24) -> Investing | C24: =IF(Setup!B24="","",Setup!C24) -> Savings | D24: =IF(B24="","",Setup!D24) -> 445 | E24: =IF(B24="","",SUMIFS(Transactions!$E$5:$E$1504,Transactions!$D$5:$D$1504,B24,Transactions!$G$5:$G$1504,$E$5,Transactions!$H$5:$H$1504,$F$5)) -> 445 | F24: =IF(B24="","",IF(C24="Income",E24-D24,D24-E24)) -> 0 | G24: =IF(OR(B24="",N(D24)=0),"",E24/D24) -> 1
B25: =IF(Setup!B25="","",Setup!B25) -> Holiday fund | C25: =IF(Setup!B25="","",Setup!C25) -> Savings | D25: =IF(B25="","",Setup!D25) -> 100 | E25: =IF(B25="","",SUMIFS(Transactions!$E$5:$E$1504,Transactions!$D$5:$D$1504,B25,Transactions!$G$5:$G$1504,$E$5,Transactions!$H$5:$H$1504,$F$5)) -> 0 | F25: =IF(B25="","",IF(C25="Income",E25-D25,D25-E25)) -> 100 | G25: =IF(OR(B25="",N(D25)=0),"",E25/D25) -> 0
B26: =IF(Setup!B26="","",Setup!B26) -> Credit card | C26: =IF(Setup!B26="","",Setup!C26) -> Debt | D26: =IF(B26="","",Setup!D26) -> 250 | E26: =IF(B26="","",SUMIFS(Transactions!$E$5:$E$1504,Transactions!$D$5:$D$1504,B26,Transactions!$G$5:$G$1504,$E$5,Transactions!$H$5:$H$1504,$F$5)) -> 250 | F26: =IF(B26="","",IF(C26="Income",E26-D26,D26-E26)) -> 0 | G26: =IF(OR(B26="",N(D26)=0),"",E26/D26) -> 1
B27: =IF(Setup!B27="","",Setup!B27) -> Student loan | C27: =IF(Setup!B27="","",Setup!C27) -> Debt | D27: =IF(B27="","",Setup!D27) -> 150 | E27: =IF(B27="","",SUMIFS(Transactions!$E$5:$E$1504,Transactions!$D$5:$D$1504,B27,Transactions!$G$5:$G$1504,$E$5,Transactions!$H$5:$H$1504,$F$5)) -> 150 | F27: =IF(B27="","",IF(C27="Income",E27-D27,D27-E27)) -> 0 | G27: =IF(OR(B27="",N(D27)=0),"",E27/D27) -> 1
B28: =IF(Setup!B28="","",Setup!B28) | C28: =IF(Setup!B28="","",Setup!C28) | D28: =IF(B28="","",Setup!D28) | E28: =IF(B28="","",SUMIFS(Transactions!$E$5:$E$1504,Transactions!$D$5:$D$1504,B28,Transactions!$G$5:$G$1504,$E$5,Transactions!$H$5:$H$1504,$F$5)) | F28: =IF(B28="","",IF(C28="Income",E28-D28,D28-E28)) | G28: =IF(OR(B28="",N(D28)=0),"",E28/D28)
B29: =IF(Setup!B29="","",Setup!B29) | C29: =IF(Setup!B29="","",Setup!C29) | D29: =IF(B29="","",Setup!D29) | E29: =IF(B29="","",SUMIFS(Transactions!$E$5:$E$1504,Transactions!$D$5:$D$1504,B29,Transactions!$G$5:$G$1504,$E$5,Transactions!$H$5:$H$1504,$F$5)) | F29: =IF(B29="","",IF(C29="Income",E29-D29,D29-E29)) | G29: =IF(OR(B29="",N(D29)=0),"",E29/D29)
B30: =IF(Setup!B30="","",Setup!B30) | C30: =IF(Setup!B30="","",Setup!C30) | D30: =IF(B30="","",Setup!D30) | E30: =IF(B30="","",SUMIFS(Transactions!$E$5:$E$1504,Transactions!$D$5:$D$1504,B30,Transactions!$G$5:$G$1504,$E$5,Transactions!$H$5:$H$1504,$F$5)) | F30: =IF(B30="","",IF(C30="Income",E30-D30,D30-E30)) | G30: =IF(OR(B30="",N(D30)=0),"",E30/D30)
B31: =IF(Setup!B31="","",Setup!B31) | C31: =IF(Setup!B31="","",Setup!C31) | D31: =IF(B31="","",Setup!D31) | E31: =IF(B31="","",SUMIFS(Transactions!$E$5:$E$1504,Transactions!$D$5:$D$1504,B31,Transactions!$G$5:$G$1504,$E$5,Transactions!$H$5:$H$1504,$F$5)) | F31: =IF(B31="","",IF(C31="Income",E31-D31,D31-E31)) | G31: =IF(OR(B31="",N(D31)=0),"",E31/D31)
B32: =IF(Setup!B32="","",Setup!B32) | C32: =IF(Setup!B32="","",Setup!C32) | D32: =IF(B32="","",Setup!D32) | E32: =IF(B32="","",SUMIFS(Transactions!$E$5:$E$1504,Transactions!$D$5:$D$1504,B32,Transactions!$G$5:$G$1504,$E$5,Transactions!$H$5:$H$1504,$F$5)) | F32: =IF(B32="","",IF(C32="Income",E32-D32,D32-E32)) | G32: =IF(OR(B32="",N(D32)=0),"",E32/D32)
... B37: =IF(Setup!B37="","",Setup!B37) | C37: =IF(Setup!B37="","",Setup!C37) | D37: =IF(B37="","",Setup!D37) | E37: =IF(B37="","",SUMIFS(Transactions!$E$5:$E$1504,Transactions!$D$5:$D$1504,B37,Transactions!$G$5:$G$1504,$E$5,Transactions!$H$5:$H$1504,$F$5)) | F37: =IF(B37="","",IF(C37="Income",E37-D37,D37-E37)) | G37: =IF(OR(B37="",N(D37)=0),"",E37/D37)

Sheet Year Dashboard
B2: Year Dashboard
B3: Your year in one screen.
B4: ="Year "&Setup!C5 -> Year 2027
B6: Month | C6: Income | D6: Needs | E6: Wants | F6: Savings | G6: Debt | H6: Left over | I6: Saving rate
B7: Jan | C7: =SUMIFS(Transactions!$E$5:$E$1504,Transactions!$F$5:$F$1504,"Income",Transactions!$G$5:$G$1504,1,Transactions!$H$5:$H$1504,Setup!$C$5) -> 4550 | D7: =SUMIFS(Transactions!$E$5:$E$1504,Transactions!$F$5:$F$1504,"Needs",Transactions!$G$5:$G$1504,1,Transactions!$H$5:$H$1504,Setup!$C$5) -> 2421.65 | E7: =SUMIFS(Transactions!$E$5:$E$1504,Transactions!$F$5:$F$1504,"Wants",Transactions!$G$5:$G$1504,1,Transactions!$H$5:$H$1504,Setup!$C$5) -> 339.81 | F7: =SUMIFS(Transactions!$E$5:$E$1504,Transactions!$F$5:$F$1504,"Savings",Transactions!$G$5:$G$1504,1,Transactions!$H$5:$H$1504,Setup!$C$5) -> 945 | G7: =SUMIFS(Transactions!$E$5:$E$1504,Transactions!$F$5:$F$1504,"Debt",Transactions!$G$5:$G$1504,1,Transactions!$H$5:$H$1504,Setup!$C$5) -> 400 | H7: =C7-SUM(D7:G7) -> 443.54 | I7: =IF(C7=0,"",(F7+G7)/C7) -> 0.2956044
B8: Feb | C8: =SUMIFS(Transactions!$E$5:$E$1504,Transactions!$F$5:$F$1504,"Income",Transactions!$G$5:$G$1504,2,Transactions!$H$5:$H$1504,Setup!$C$5) -> 4720 | D8: =SUMIFS(Transactions!$E$5:$E$1504,Transactions!$F$5:$F$1504,"Needs",Transactions!$G$5:$G$1504,2,Transactions!$H$5:$H$1504,Setup!$C$5) -> 2427.05 | E8: =SUMIFS(Transactions!$E$5:$E$1504,Transactions!$F$5:$F$1504,"Wants",Transactions!$G$5:$G$1504,2,Transactions!$H$5:$H$1504,Setup!$C$5) -> 321.72 | F8: =SUMIFS(Transactions!$E$5:$E$1504,Transactions!$F$5:$F$1504,"Savings",Transactions!$G$5:$G$1504,2,Transactions!$H$5:$H$1504,Setup!$C$5) -> 945 | G8: =SUMIFS(Transactions!$E$5:$E$1504,Transactions!$F$5:$F$1504,"Debt",Transactions!$G$5:$G$1504,2,Transactions!$H$5:$H$1504,Setup!$C$5) -> 400 | H8: =C8-SUM(D8:G8) -> 626.23 | I8: =IF(C8=0,"",(F8+G8)/C8) -> 0.28495763
B9: Mar | C9: =SUMIFS(Transactions!$E$5:$E$1504,Transactions!$F$5:$F$1504,"Income",Transactions!$G$5:$G$1504,3,Transactions!$H$5:$H$1504,Setup!$C$5) -> 4600 | D9: =SUMIFS(Transactions!$E$5:$E$1504,Transactions!$F$5:$F$1504,"Needs",Transactions!$G$5:$G$1504,3,Transactions!$H$5:$H$1504,Setup!$C$5) -> 2496.16 | E9: =SUMIFS(Transactions!$E$5:$E$1504,Transactions!$F$5:$F$1504,"Wants",Transactions!$G$5:$G$1504,3,Transactions!$H$5:$H$1504,Setup!$C$5) -> 454.69 | F9: =SUMIFS(Transactions!$E$5:$E$1504,Transactions!$F$5:$F$1504,"Savings",Transactions!$G$5:$G$1504,3,Transactions!$H$5:$H$1504,Setup!$C$5) -> 945 | G9: =SUMIFS(Transactions!$E$5:$E$1504,Transactions!$F$5:$F$1504,"Debt",Transactions!$G$5:$G$1504,3,Transactions!$H$5:$H$1504,Setup!$C$5) -> 400 | H9: =C9-SUM(D9:G9) -> 304.15 | I9: =IF(C9=0,"",(F9+G9)/C9) -> 0.2923913
B10: Apr | C10: =SUMIFS(Transactions!$E$5:$E$1504,Transactions!$F$5:$F$1504,"Income",Transactions!$G$5:$G$1504,4,Transactions!$H$5:$H$1504,Setup!$C$5) -> 0 | D10: =SUMIFS(Transactions!$E$5:$E$1504,Transactions!$F$5:$F$1504,"Needs",Transactions!$G$5:$G$1504,4,Transactions!$H$5:$H$1504,Setup!$C$5) -> 0 | E10: =SUMIFS(Transactions!$E$5:$E$1504,Transactions!$F$5:$F$1504,"Wants",Transactions!$G$5:$G$1504,4,Transactions!$H$5:$H$1504,Setup!$C$5) -> 0 | F10: =SUMIFS(Transactions!$E$5:$E$1504,Transactions!$F$5:$F$1504,"Savings",Transactions!$G$5:$G$1504,4,Transactions!$H$5:$H$1504,Setup!$C$5) -> 0 | G10: =SUMIFS(Transactions!$E$5:$E$1504,Transactions!$F$5:$F$1504,"Debt",Transactions!$G$5:$G$1504,4,Transactions!$H$5:$H$1504,Setup!$C$5) -> 0 | H10: =C10-SUM(D10:G10) -> 0 | I10: =IF(C10=0,"",(F10+G10)/C10)
B11: May | C11: =SUMIFS(Transactions!$E$5:$E$1504,Transactions!$F$5:$F$1504,"Income",Transactions!$G$5:$G$1504,5,Transactions!$H$5:$H$1504,Setup!$C$5) -> 0 | D11: =SUMIFS(Transactions!$E$5:$E$1504,Transactions!$F$5:$F$1504,"Needs",Transactions!$G$5:$G$1504,5,Transactions!$H$5:$H$1504,Setup!$C$5) -> 0 | E11: =SUMIFS(Transactions!$E$5:$E$1504,Transactions!$F$5:$F$1504,"Wants",Transactions!$G$5:$G$1504,5,Transactions!$H$5:$H$1504,Setup!$C$5) -> 0 | F11: =SUMIFS(Transactions!$E$5:$E$1504,Transactions!$F$5:$F$1504,"Savings",Transactions!$G$5:$G$1504,5,Transactions!$H$5:$H$1504,Setup!$C$5) -> 0 | G11: =SUMIFS(Transactions!$E$5:$E$1504,Transactions!$F$5:$F$1504,"Debt",Transactions!$G$5:$G$1504,5,Transactions!$H$5:$H$1504,Setup!$C$5) -> 0 | H11: =C11-SUM(D11:G11) -> 0 | I11: =IF(C11=0,"",(F11+G11)/C11)
B12: Jun | C12: =SUMIFS(Transactions!$E$5:$E$1504,Transactions!$F$5:$F$1504,"Income",Transactions!$G$5:$G$1504,6,Transactions!$H$5:$H$1504,Setup!$C$5) -> 0 | D12: =SUMIFS(Transactions!$E$5:$E$1504,Transactions!$F$5:$F$1504,"Needs",Transactions!$G$5:$G$1504,6,Transactions!$H$5:$H$1504,Setup!$C$5) -> 0 | E12: =SUMIFS(Transactions!$E$5:$E$1504,Transactions!$F$5:$F$1504,"Wants",Transactions!$G$5:$G$1504,6,Transactions!$H$5:$H$1504,Setup!$C$5) -> 0 | F12: =SUMIFS(Transactions!$E$5:$E$1504,Transactions!$F$5:$F$1504,"Savings",Transactions!$G$5:$G$1504,6,Transactions!$H$5:$H$1504,Setup!$C$5) -> 0 | G12: =SUMIFS(Transactions!$E$5:$E$1504,Transactions!$F$5:$F$1504,"Debt",Transactions!$G$5:$G$1504,6,Transactions!$H$5:$H$1504,Setup!$C$5) -> 0 | H12: =C12-SUM(D12:G12) -> 0 | I12: =IF(C12=0,"",(F12+G12)/C12)
B13: Jul | C13: =SUMIFS(Transactions!$E$5:$E$1504,Transactions!$F$5:$F$1504,"Income",Transactions!$G$5:$G$1504,7,Transactions!$H$5:$H$1504,Setup!$C$5) -> 0 | D13: =SUMIFS(Transactions!$E$5:$E$1504,Transactions!$F$5:$F$1504,"Needs",Transactions!$G$5:$G$1504,7,Transactions!$H$5:$H$1504,Setup!$C$5) -> 0 | E13: =SUMIFS(Transactions!$E$5:$E$1504,Transactions!$F$5:$F$1504,"Wants",Transactions!$G$5:$G$1504,7,Transactions!$H$5:$H$1504,Setup!$C$5) -> 0 | F13: =SUMIFS(Transactions!$E$5:$E$1504,Transactions!$F$5:$F$1504,"Savings",Transactions!$G$5:$G$1504,7,Transactions!$H$5:$H$1504,Setup!$C$5) -> 0 | G13: =SUMIFS(Transactions!$E$5:$E$1504,Transactions!$F$5:$F$1504,"Debt",Transactions!$G$5:$G$1504,7,Transactions!$H$5:$H$1504,Setup!$C$5) -> 0 | H13: =C13-SUM(D13:G13) -> 0 | I13: =IF(C13=0,"",(F13+G13)/C13)
B14: Aug | C14: =SUMIFS(Transactions!$E$5:$E$1504,Transactions!$F$5:$F$1504,"Income",Transactions!$G$5:$G$1504,8,Transactions!$H$5:$H$1504,Setup!$C$5) -> 0 | D14: =SUMIFS(Transactions!$E$5:$E$1504,Transactions!$F$5:$F$1504,"Needs",Transactions!$G$5:$G$1504,8,Transactions!$H$5:$H$1504,Setup!$C$5) -> 0 | E14: =SUMIFS(Transactions!$E$5:$E$1504,Transactions!$F$5:$F$1504,"Wants",Transactions!$G$5:$G$1504,8,Transactions!$H$5:$H$1504,Setup!$C$5) -> 0 | F14: =SUMIFS(Transactions!$E$5:$E$1504,Transactions!$F$5:$F$1504,"Savings",Transactions!$G$5:$G$1504,8,Transactions!$H$5:$H$1504,Setup!$C$5) -> 0 | G14: =SUMIFS(Transactions!$E$5:$E$1504,Transactions!$F$5:$F$1504,"Debt",Transactions!$G$5:$G$1504,8,Transactions!$H$5:$H$1504,Setup!$C$5) -> 0 | H14: =C14-SUM(D14:G14) -> 0 | I14: =IF(C14=0,"",(F14+G14)/C14)
B15: Sep | C15: =SUMIFS(Transactions!$E$5:$E$1504,Transactions!$F$5:$F$1504,"Income",Transactions!$G$5:$G$1504,9,Transactions!$H$5:$H$1504,Setup!$C$5) -> 0 | D15: =SUMIFS(Transactions!$E$5:$E$1504,Transactions!$F$5:$F$1504,"Needs",Transactions!$G$5:$G$1504,9,Transactions!$H$5:$H$1504,Setup!$C$5) -> 0 | E15: =SUMIFS(Transactions!$E$5:$E$1504,Transactions!$F$5:$F$1504,"Wants",Transactions!$G$5:$G$1504,9,Transactions!$H$5:$H$1504,Setup!$C$5) -> 0 | F15: =SUMIFS(Transactions!$E$5:$E$1504,Transactions!$F$5:$F$1504,"Savings",Transactions!$G$5:$G$1504,9,Transactions!$H$5:$H$1504,Setup!$C$5) -> 0 | G15: =SUMIFS(Transactions!$E$5:$E$1504,Transactions!$F$5:$F$1504,"Debt",Transactions!$G$5:$G$1504,9,Transactions!$H$5:$H$1504,Setup!$C$5) -> 0 | H15: =C15-SUM(D15:G15) -> 0 | I15: =IF(C15=0,"",(F15+G15)/C15)
B16: Oct | C16: =SUMIFS(Transactions!$E$5:$E$1504,Transactions!$F$5:$F$1504,"Income",Transactions!$G$5:$G$1504,10,Transactions!$H$5:$H$1504,Setup!$C$5) -> 0 | D16: =SUMIFS(Transactions!$E$5:$E$1504,Transactions!$F$5:$F$1504,"Needs",Transactions!$G$5:$G$1504,10,Transactions!$H$5:$H$1504,Setup!$C$5) -> 0 | E16: =SUMIFS(Transactions!$E$5:$E$1504,Transactions!$F$5:$F$1504,"Wants",Transactions!$G$5:$G$1504,10,Transactions!$H$5:$H$1504,Setup!$C$5) -> 0 | F16: =SUMIFS(Transactions!$E$5:$E$1504,Transactions!$F$5:$F$1504,"Savings",Transactions!$G$5:$G$1504,10,Transactions!$H$5:$H$1504,Setup!$C$5) -> 0 | G16: =SUMIFS(Transactions!$E$5:$E$1504,Transactions!$F$5:$F$1504,"Debt",Transactions!$G$5:$G$1504,10,Transactions!$H$5:$H$1504,Setup!$C$5) -> 0 | H16: =C16-SUM(D16:G16) -> 0 | I16: =IF(C16=0,"",(F16+G16)/C16)
B17: Nov | C17: =SUMIFS(Transactions!$E$5:$E$1504,Transactions!$F$5:$F$1504,"Income",Transactions!$G$5:$G$1504,11,Transactions!$H$5:$H$1504,Setup!$C$5) -> 0 | D17: =SUMIFS(Transactions!$E$5:$E$1504,Transactions!$F$5:$F$1504,"Needs",Transactions!$G$5:$G$1504,11,Transactions!$H$5:$H$1504,Setup!$C$5) -> 0 | E17: =SUMIFS(Transactions!$E$5:$E$1504,Transactions!$F$5:$F$1504,"Wants",Transactions!$G$5:$G$1504,11,Transactions!$H$5:$H$1504,Setup!$C$5) -> 0 | F17: =SUMIFS(Transactions!$E$5:$E$1504,Transactions!$F$5:$F$1504,"Savings",Transactions!$G$5:$G$1504,11,Transactions!$H$5:$H$1504,Setup!$C$5) -> 0 | G17: =SUMIFS(Transactions!$E$5:$E$1504,Transactions!$F$5:$F$1504,"Debt",Transactions!$G$5:$G$1504,11,Transactions!$H$5:$H$1504,Setup!$C$5) -> 0 | H17: =C17-SUM(D17:G17) -> 0 | I17: =IF(C17=0,"",(F17+G17)/C17)
B18: Dec | C18: =SUMIFS(Transactions!$E$5:$E$1504,Transactions!$F$5:$F$1504,"Income",Transactions!$G$5:$G$1504,12,Transactions!$H$5:$H$1504,Setup!$C$5) -> 0 | D18: =SUMIFS(Transactions!$E$5:$E$1504,Transactions!$F$5:$F$1504,"Needs",Transactions!$G$5:$G$1504,12,Transactions!$H$5:$H$1504,Setup!$C$5) -> 0 | E18: =SUMIFS(Transactions!$E$5:$E$1504,Transactions!$F$5:$F$1504,"Wants",Transactions!$G$5:$G$1504,12,Transactions!$H$5:$H$1504,Setup!$C$5) -> 0 | F18: =SUMIFS(Transactions!$E$5:$E$1504,Transactions!$F$5:$F$1504,"Savings",Transactions!$G$5:$G$1504,12,Transactions!$H$5:$H$1504,Setup!$C$5) -> 0 | G18: =SUMIFS(Transactions!$E$5:$E$1504,Transactions!$F$5:$F$1504,"Debt",Transactions!$G$5:$G$1504,12,Transactions!$H$5:$H$1504,Setup!$C$5) -> 0 | H18: =C18-SUM(D18:G18) -> 0 | I18: =IF(C18=0,"",(F18+G18)/C18)
B19: Total | C19: =SUM(C7:C18) -> 13870 | D19: =SUM(D7:D18) -> 7344.86 | E19: =SUM(E7:E18) -> 1116.22 | F19: =SUM(F7:F18) -> 2835 | G19: =SUM(G7:G18) -> 1200 | H19: =SUM(H7:H18) -> 1373.92 | I19: =IF(C19=0,"",(F19+G19)/C19) -> 0.29091565

Sheet Debt Payoff
B2: Debt Payoff
B3: List debts in the order you want to clear them. Snowball: smallest balance first. Avalanche: highest interest first.
B5: Debt | C5: Balance | D5: APR | E5: Min payment | F5: Paid off in | H5: Your plan
B6: Credit card | C6: 3200 | D6: 0.229 | E6: 95 | F6: =IF(N(C6)=0,"",IF(COUNTIF(U41:U160,">0.005")>=120,"10+ years",TEXT(EDATE($C$13,COUNTIF(U41:U160,">0.005")),"mmm yyyy"))) -> Apr 2028 | H6: Debt-free in | I6: =IF(COUNTIF(Z41:Z160,">0.005")>=120,"10+ years",COUNTIF(Z41:Z160,">0.005")+1&" months") -> 46 months
B7: Car loan | C7: 8400 | D7: 0.065 | E7: 240 | F7: =IF(N(C7)=0,"",IF(COUNTIF(V41:V160,">0.005")>=120,"10+ years",TEXT(EDATE($C$13,COUNTIF(V41:V160,">0.005")),"mmm yyyy"))) -> Mar 2029 | H7: Debt-free by | I7: =IF(COUNTIF(Z41:Z160,">0.005")>=120,"Pay more each month",TEXT(EDATE($C$13,COUNTIF(Z41:Z160,">0.005")),"mmmm yyyy")) -> October 2030
B8: Student loan | C8: 14500 | D8: 0.05 | E8: 160 | F8: =IF(N(C8)=0,"",IF(COUNTIF(W41:W160,">0.005")>=120,"10+ years",TEXT(EDATE($C$13,COUNTIF(W41:W160,">0.005")),"mmm yyyy"))) -> Oct 2030 | H8: Starting debt | I8: =SUM(C6:C10) -> 26100
F9: =IF(N(C9)=0,"",IF(COUNTIF(X41:X160,">0.005")>=120,"10+ years",TEXT(EDATE($C$13,COUNTIF(X41:X160,">0.005")),"mmm yyyy"))) | H9: Total interest you'll pay | I9: =SUM(P41:T160)-I8 -> 3220.6467
F10: =IF(N(C10)=0,"",IF(COUNTIF(Y41:Y160,">0.005")>=120,"10+ years",TEXT(EDATE($C$13,COUNTIF(Y41:Y160,">0.005")),"mmm yyyy")))
H11: =IF(C14<SUM(E6:E10),"Total paid is below your minimum payments. Raise the extra amount.","")
B12: Extra paid each month | C12: 150
B13: First payment month | C13: 46388
B14: Total paid each month | C14: =SUM(E6:E10)+C12 -> 645
B39: Month-by-month schedule (calculated)
J40: Month | K40: Owed 1 | L40: Owed 2 | M40: Owed 3 | N40: Owed 4 | O40: Owed 5 | P40: Pay 1 | Q40: Pay 2 | R40: Pay 3 | S40: Pay 4 | T40: Pay 5 | U40: Balance 1 | V40: Balance 2 | W40: Balance 3 | X40: Balance 4 | Y40: Balance 5 | Z40: Total balance
J41: =EDATE($C$13,0) -> 46388 | K41: =N($C$6)*(1+N($D$6)/12) -> 3261.0667 | L41: =N($C$7)*(1+N($D$7)/12) -> 8445.5 | M41: =N($C$8)*(1+N($D$8)/12) -> 14560.417 | N41: =N($C$9)*(1+N($D$9)/12) -> 0 | O41: =N($C$10)*(1+N($D$10)/12) -> 0 | P41: =MAX(0,MIN(K41,$C$14-(0)-(MIN(L41,N($E$7))+MIN(M41,N($E$8))+MIN(N41,N($E$9))+MIN(O41,N($E$10))))) -> 245 | Q41: =MAX(0,MIN(L41,$C$14-(P41)-(MIN(M41,N($E$8))+MIN(N41,N($E$9))+MIN(O41,N($E$10))))) -> 240 | R41: =MAX(0,MIN(M41,$C$14-(P41+Q41)-(MIN(N41,N($E$9))+MIN(O41,N($E$10))))) -> 160 | S41: =MAX(0,MIN(N41,$C$14-(P41+Q41+R41)-(MIN(O41,N($E$10))))) -> 0 | T41: =MAX(0,MIN(O41,$C$14-(P41+Q41+R41+S41)-(0))) -> 0 | U41: =ROUND(K41-P41,2) -> 3016.07 | V41: =ROUND(L41-Q41,2) -> 8205.5 | W41: =ROUND(M41-R41,2) -> 14400.42 | X41: =ROUND(N41-S41,2) -> 0 | Y41: =ROUND(O41-T41,2) -> 0 | Z41: =SUM(U41:Y41) -> 25621.99
J42: =EDATE($C$13,1) -> 46419 | K42: =U41*(1+N($D$6)/12) -> 3073.6267 | L42: =V41*(1+N($D$7)/12) -> 8249.9465 | M42: =W41*(1+N($D$8)/12) -> 14460.422 | N42: =X41*(1+N($D$9)/12) -> 0 | O42: =Y41*(1+N($D$10)/12) -> 0 | P42: =MAX(0,MIN(K42,$C$14-(0)-(MIN(L42,N($E$7))+MIN(M42,N($E$8))+MIN(N42,N($E$9))+MIN(O42,N($E$10))))) -> 245 | Q42: =MAX(0,MIN(L42,$C$14-(P42)-(MIN(M42,N($E$8))+MIN(N42,N($E$9))+MIN(O42,N($E$10))))) -> 240 | R42: =MAX(0,MIN(M42,$C$14-(P42+Q42)-(MIN(N42,N($E$9))+MIN(O42,N($E$10))))) -> 160 | S42: =MAX(0,MIN(N42,$C$14-(P42+Q42+R42)-(MIN(O42,N($E$10))))) -> 0 | T42: =MAX(0,MIN(O42,$C$14-(P42+Q42+R42+S42)-(0))) -> 0 | U42: =ROUND(K42-P42,2) -> 2828.63 | V42: =ROUND(L42-Q42,2) -> 8009.95 | W42: =ROUND(M42-R42,2) -> 14300.42 | X42: =ROUND(N42-S42,2) -> 0 | Y42: =ROUND(O42-T42,2) -> 0 | Z42: =SUM(U42:Y42) -> 25139
J43: =EDATE($C$13,2) -> 46447 | K43: =U42*(1+N($D$6)/12) -> 2882.6097 | L43: =V42*(1+N($D$7)/12) -> 8053.3372 | M43: =W42*(1+N($D$8)/12) -> 14360.005 | N43: =X42*(1+N($D$9)/12) -> 0 | O43: =Y42*(1+N($D$10)/12) -> 0 | P43: =MAX(0,MIN(K43,$C$14-(0)-(MIN(L43,N($E$7))+MIN(M43,N($E$8))+MIN(N43,N($E$9))+MIN(O43,N($E$10))))) -> 245 | Q43: =MAX(0,MIN(L43,$C$14-(P43)-(MIN(M43,N($E$8))+MIN(N43,N($E$9))+MIN(O43,N($E$10))))) -> 240 | R43: =MAX(0,MIN(M43,$C$14-(P43+Q43)-(MIN(N43,N($E$9))+MIN(O43,N($E$10))))) -> 160 | S43: =MAX(0,MIN(N43,$C$14-(P43+Q43+R43)-(MIN(O43,N($E$10))))) -> 0 | T43: =MAX(0,MIN(O43,$C$14-(P43+Q43+R43+S43)-(0))) -> 0 | U43: =ROUND(K43-P43,2) -> 2637.61 | V43: =ROUND(L43-Q43,2) -> 7813.34 | W43: =ROUND(M43-R43,2) -> 14200.01 | X43: =ROUND(N43-S43,2) -> 0 | Y43: =ROUND(O43-T43,2) -> 0 | Z43: =SUM(U43:Y43) -> 24650.96
J44: =EDATE($C$13,3) -> 46478 | K44: =U43*(1+N($D$6)/12) -> 2687.9444 | L44: =V43*(1+N($D$7)/12) -> 7855.6623 | M44: =W43*(1+N($D$8)/12) -> 14259.177 | N44: =X43*(1+N($D$9)/12) -> 0 | O44: =Y43*(1+N($D$10)/12) -> 0 | P44: =MAX(0,MIN(K44,$C$14-(0)-(MIN(L44,N($E$7))+MIN(M44,N($E$8))+MIN(N44,N($E$9))+MIN(O44,N($E$10))))) -> 245 | Q44: =MAX(0,MIN(L44,$C$14-(P44)-(MIN(M44,N($E$8))+MIN(N44,N($E$9))+MIN(O44,N($E$10))))) -> 240 | R44: =MAX(0,MIN(M44,$C$14-(P44+Q44)-(MIN(N44,N($E$9))+MIN(O44,N($E$10))))) -> 160 | S44: =MAX(0,MIN(N44,$C$14-(P44+Q44+R44)-(MIN(O44,N($E$10))))) -> 0 | T44: =MAX(0,MIN(O44,$C$14-(P44+Q44+R44+S44)-(0))) -> 0 | U44: =ROUND(K44-P44,2) -> 2442.94 | V44: =ROUND(L44-Q44,2) -> 7615.66 | W44: =ROUND(M44-R44,2) -> 14099.18 | X44: =ROUND(N44-S44,2) -> 0 | Y44: =ROUND(O44-T44,2) -> 0 | Z44: =SUM(U44:Y44) -> 24157.78
J45: =EDATE($C$13,4) -> 46508 | K45: =U44*(1+N($D$6)/12) -> 2489.5594 | L45: =V44*(1+N($D$7)/12) -> 7656.9115 | M45: =W44*(1+N($D$8)/12) -> 14157.927 | N45: =X44*(1+N($D$9)/12) -> 0 | O45: =Y44*(1+N($D$10)/12) -> 0 | P45: =MAX(0,MIN(K45,$C$14-(0)-(MIN(L45,N($E$7))+MIN(M45,N($E$8))+MIN(N45,N($E$9))+MIN(O45,N($E$10))))) -> 245 | Q45: =MAX(0,MIN(L45,$C$14-(P45)-(MIN(M45,N($E$8))+MIN(N45,N($E$9))+MIN(O45,N($E$10))))) -> 240 | R45: =MAX(0,MIN(M45,$C$14-(P45+Q45)-(MIN(N45,N($E$9))+MIN(O45,N($E$10))))) -> 160 | S45: =MAX(0,MIN(N45,$C$14-(P45+Q45+R45)-(MIN(O45,N($E$10))))) -> 0 | T45: =MAX(0,MIN(O45,$C$14-(P45+Q45+R45+S45)-(0))) -> 0 | U45: =ROUND(K45-P45,2) -> 2244.56 | V45: =ROUND(L45-Q45,2) -> 7416.91 | W45: =ROUND(M45-R45,2) -> 13997.93 | X45: =ROUND(N45-S45,2) -> 0 | Y45: =ROUND(O45-T45,2) -> 0 | Z45: =SUM(U45:Y45) -> 23659.4
J46: =EDATE($C$13,5) -> 46539 | K46: =U45*(1+N($D$6)/12) -> 2287.3937 | L46: =V45*(1+N($D$7)/12) -> 7457.0849 | M46: =W45*(1+N($D$8)/12) -> 14056.255 | N46: =X45*(1+N($D$9)/12) -> 0 | O46: =Y45*(1+N($D$10)/12) -> 0 | P46: =MAX(0,MIN(K46,$C$14-(0)-(MIN(L46,N($E$7))+MIN(M46,N($E$8))+MIN(N46,N($E$9))+MIN(O46,N($E$10))))) -> 245 | Q46: =MAX(0,MIN(L46,$C$14-(P46)-(MIN(M46,N($E$8))+MIN(N46,N($E$9))+MIN(O46,N($E$10))))) -> 240 | R46: =MAX(0,MIN(M46,$C$14-(P46+Q46)-(MIN(N46,N($E$9))+MIN(O46,N($E$10))))) -> 160 | S46: =MAX(0,MIN(N46,$C$14-(P46+Q46+R46)-(MIN(O46,N($E$10))))) -> 0 | T46: =MAX(0,MIN(O46,$C$14-(P46+Q46+R46+S46)-(0))) -> 0 | U46: =ROUND(K46-P46,2) -> 2042.39 | V46: =ROUND(L46-Q46,2) -> 7217.08 | W46: =ROUND(M46-R46,2) -> 13896.25 | X46: =ROUND(N46-S46,2) -> 0 | Y46: =ROUND(O46-T46,2) -> 0 | Z46: =SUM(U46:Y46) -> 23155.72
J47: =EDATE($C$13,6) -> 46569 | K47: =U46*(1+N($D$6)/12) -> 2081.3656 | L47: =V46*(1+N($D$7)/12) -> 7256.1725 | M47: =W46*(1+N($D$8)/12) -> 13954.151 | N47: =X46*(1+N($D$9)/12) -> 0 | O47: =Y46*(1+N($D$10)/12) -> 0 | P47: =MAX(0,MIN(K47,$C$14-(0)-(MIN(L47,N($E$7))+MIN(M47,N($E$8))+MIN(N47,N($E$9))+MIN(O47,N($E$10))))) -> 245 | Q47: =MAX(0,MIN(L47,$C$14-(P47)-(MIN(M47,N($E$8))+MIN(N47,N($E$9))+MIN(O47,N($E$10))))) -> 240 | R47: =MAX(0,MIN(M47,$C$14-(P47+Q47)-(MIN(N47,N($E$9))+MIN(O47,N($E$10))))) -> 160 | S47: =MAX(0,MIN(N47,$C$14-(P47+Q47+R47)-(MIN(O47,N($E$10))))) -> 0 | T47: =MAX(0,MIN(O47,$C$14-(P47+Q47+R47+S47)-(0))) -> 0 | U47: =ROUND(K47-P47,2) -> 1836.37 | V47: =ROUND(L47-Q47,2) -> 7016.17 | W47: =ROUND(M47-R47,2) -> 13794.15 | X47: =ROUND(N47-S47,2) -> 0 | Y47: =ROUND(O47-T47,2) -> 0 | Z47: =SUM(U47:Y47) -> 22646.69
J48: =EDATE($C$13,7) -> 46600 | K48: =U47*(1+N($D$6)/12) -> 1871.4141 | L48: =V47*(1+N($D$7)/12) -> 7054.1743 | M48: =W47*(1+N($D$8)/12) -> 13851.626 | N48: =X47*(1+N($D$9)/12) -> 0 | O48: =Y47*(1+N($D$10)/12) -> 0 | P48: =MAX(0,MIN(K48,$C$14-(0)-(MIN(L48,N($E$7))+MIN(M48,N($E$8))+MIN(N48,N($E$9))+MIN(O48,N($E$10))))) -> 245 | Q48: =MAX(0,MIN(L48,$C$14-(P48)-(MIN(M48,N($E$8))+MIN(N48,N($E$9))+MIN(O48,N($E$10))))) -> 240 | R48: =MAX(0,MIN(M48,$C$14-(P48+Q48)-(MIN(N48,N($E$9))+MIN(O48,N($E$10))))) -> 160 | S48: =MAX(0,MIN(N48,$C$14-(P48+Q48+R48)-(MIN(O48,N($E$10))))) -> 0 | T48: =MAX(0,MIN(O48,$C$14-(P48+Q48+R48+S48)-(0))) -> 0 | U48: =ROUND(K48-P48,2) -> 1626.41 | V48: =ROUND(L48-Q48,2) -> 6814.17 | W48: =ROUND(M48-R48,2) -> 13691.63 | X48: =ROUND(N48-S48,2) -> 0 | Y48: =ROUND(O48-T48,2) -> 0 | Z48: =SUM(U48:Y48) -> 22132.21
J49: =EDATE($C$13,8) -> 46631 | K49: =U48*(1+N($D$6)/12) -> 1657.4473 | L49: =V48*(1+N($D$7)/12) -> 6851.0801 | M49: =W48*(1+N($D$8)/12) -> 13748.678 | N49: =X48*(1+N($D$9)/12) -> 0 | O49: =Y48*(1+N($D$10)/12) -> 0 | P49: =MAX(0,MIN(K49,$C$14-(0)-(MIN(L49,N($E$7))+MIN(M49,N($E$8))+MIN(N49,N($E$9))+MIN(O49,N($E$10))))) -> 245 | Q49: =MAX(0,MIN(L49,$C$14-(P49)-(MIN(M49,N($E$8))+MIN(N49,N($E$9))+MIN(O49,N($E$10))))) -> 240 | R49: =MAX(0,MIN(M49,$C$14-(P49+Q49)-(MIN(N49,N($E$9))+MIN(O49,N($E$10))))) -> 160 | S49: =MAX(0,MIN(N49,$C$14-(P49+Q49+R49)-(MIN(O49,N($E$10))))) -> 0 | T49: =MAX(0,MIN(O49,$C$14-(P49+Q49+R49+S49)-(0))) -> 0 | U49: =ROUND(K49-P49,2) -> 1412.45 | V49: =ROUND(L49-Q49,2) -> 6611.08 | W49: =ROUND(M49-R49,2) -> 13588.68 | X49: =ROUND(N49-S49,2) -> 0 | Y49: =ROUND(O49-T49,2) -> 0 | Z49: =SUM(U49:Y49) -> 21612.21
J50: =EDATE($C$13,9) -> 46661 | K50: =U49*(1+N($D$6)/12) -> 1439.4043 | L50: =V49*(1+N($D$7)/12) -> 6646.89 | M50: =W49*(1+N($D$8)/12) -> 13645.299 | N50: =X49*(1+N($D$9)/12) -> 0 | O50: =Y49*(1+N($D$10)/12) -> 0 | P50: =MAX(0,MIN(K50,$C$14-(0)-(MIN(L50,N($E$7))+MIN(M50,N($E$8))+MIN(N50,N($E$9))+MIN(O50,N($E$10))))) -> 245 | Q50: =MAX(0,MIN(L50,$C$14-(P50)-(MIN(M50,N($E$8))+MIN(N50,N($E$9))+MIN(O50,N($E$10))))) -> 240 | R50: =MAX(0,MIN(M50,$C$14-(P50+Q50)-(MIN(N50,N($E$9))+MIN(O50,N($E$10))))) -> 160 | S50: =MAX(0,MIN(N50,$C$14-(P50+Q50+R50)-(MIN(O50,N($E$10))))) -> 0 | T50: =MAX(0,MIN(O50,$C$14-(P50+Q50+R50+S50)-(0))) -> 0 | U50: =ROUND(K50-P50,2) -> 1194.4 | V50: =ROUND(L50-Q50,2) -> 6406.89 | W50: =ROUND(M50-R50,2) -> 13485.3 | X50: =ROUND(N50-S50,2) -> 0 | Y50: =ROUND(O50-T50,2) -> 0 | Z50: =SUM(U50:Y50) -> 21086.59
J51: =EDATE($C$13,10) -> 46692 | K51: =U50*(1+N($D$6)/12) -> 1217.1931 | L51: =V50*(1+N($D$7)/12) -> 6441.594 | M51: =W50*(1+N($D$8)/12) -> 13541.489 | N51: =X50*(1+N($D$9)/12) -> 0 | O51: =Y50*(1+N($D$10)/12) -> 0 | P51: =MAX(0,MIN(K51,$C$14-(0)-(MIN(L51,N($E$7))+MIN(M51,N($E$8))+MIN(N51,N($E$9))+MIN(O51,N($E$10))))) -> 245 | Q51: =MAX(0,MIN(L51,$C$14-(P51)-(MIN(M51,N($E$8))+MIN(N51,N($E$9))+MIN(O51,N($E$10))))) -> 240 | R51: =MAX(0,MIN(M51,$C$14-(P51+Q51)-(MIN(N51,N($E$9))+MIN(O51,N($E$10))))) -> 160 | S51: =MAX(0,MIN(N51,$C$14-(P51+Q51+R51)-(MIN(O51,N($E$10))))) -> 0 | T51: =MAX(0,MIN(O51,$C$14-(P51+Q51+R51+S51)-(0))) -> 0 | U51: =ROUND(K51-P51,2) -> 972.19 | V51: =ROUND(L51-Q51,2) -> 6201.59 | W51: =ROUND(M51-R51,2) -> 13381.49 | X51: =ROUND(N51-S51,2) -> 0 | Y51: =ROUND(O51-T51,2) -> 0 | Z51: =SUM(U51:Y51) -> 20555.27
J52: =EDATE($C$13,11) -> 46722 | K52: =U51*(1+N($D$6)/12) -> 990.74263 | L52: =V51*(1+N($D$7)/12) -> 6235.1819 | M52: =W51*(1+N($D$8)/12) -> 13437.246 | N52: =X51*(1+N($D$9)/12) -> 0 | O52: =Y51*(1+N($D$10)/12) -> 0 | P52: =MAX(0,MIN(K52,$C$14-(0)-(MIN(L52,N($E$7))+MIN(M52,N($E$8))+MIN(N52,N($E$9))+MIN(O52,N($E$10))))) -> 245 | Q52: =MAX(0,MIN(L52,$C$14-(P52)-(MIN(M52,N($E$8))+MIN(N52,N($E$9))+MIN(O52,N($E$10))))) -> 240 | R52: =MAX(0,MIN(M52,$C$14-(P52+Q52)-(MIN(N52,N($E$9))+MIN(O52,N($E$10))))) -> 160 | S52: =MAX(0,MIN(N52,$C$14-(P52+Q52+R52)-(MIN(O52,N($E$10))))) -> 0 | T52: =MAX(0,MIN(O52,$C$14-(P52+Q52+R52+S52)-(0))) -> 0 | U52: =ROUND(K52-P52,2) -> 745.74 | V52: =ROUND(L52-Q52,2) -> 5995.18 | W52: =ROUND(M52-R52,2) -> 13277.25 | X52: =ROUND(N52-S52,2) -> 0 | Y52: =ROUND(O52-T52,2) -> 0 | Z52: =SUM(U52:Y52) -> 20018.17
J53: =EDATE($C$13,12) -> 46753 | K53: =U52*(1+N($D$6)/12) -> 759.97121 | L53: =V52*(1+N($D$7)/12) -> 6027.6539 | M53: =W52*(1+N($D$8)/12) -> 13332.572 | N53: =X52*(1+N($D$9)/12) -> 0 | O53: =Y52*(1+N($D$10)/12) -> 0 | P53: =MAX(0,MIN(K53,$C$14-(0)-(MIN(L53,N($E$7))+MIN(M53,N($E$8))+MIN(N53,N($E$9))+MIN(O53,N($E$10))))) -> 245 | Q53: =MAX(0,MIN(L53,$C$14-(P53)-(MIN(M53,N($E$8))+MIN(N53,N($E$9))+MIN(O53,N($E$10))))) -> 240 | R53: =MAX(0,MIN(M53,$C$14-(P53+Q53)-(MIN(N53,N($E$9))+MIN(O53,N($E$10))))) -> 160 | S53: =MAX(0,MIN(N53,$C$14-(P53+Q53+R53)-(MIN(O53,N($E$10))))) -> 0 | T53: =MAX(0,MIN(O53,$C$14-(P53+Q53+R53+S53)-(0))) -> 0 | U53: =ROUND(K53-P53,2) -> 514.97 | V53: =ROUND(L53-Q53,2) -> 5787.65 | W53: =ROUND(M53-R53,2) -> 13172.57 | X53: =ROUND(N53-S53,2) -> 0 | Y53: =ROUND(O53-T53,2) -> 0 | Z53: =SUM(U53:Y53) -> 19475.19
J54: =EDATE($C$13,13) -> 46784 | K54: =U53*(1+N($D$6)/12) -> 524.79734 | L54: =V53*(1+N($D$7)/12) -> 5818.9998 | M54: =W53*(1+N($D$8)/12) -> 13227.456 | N54: =X53*(1+N($D$9)/12) -> 0 | O54: =Y53*(1+N($D$10)/12) -> 0 | P54: =MAX(0,MIN(K54,$C$14-(0)-(MIN(L54,N($E$7))+MIN(M54,N($E$8))+MIN(N54,N($E$9))+MIN(O54,N($E$10))))) -> 245 | Q54: =MAX(0,MIN(L54,$C$14-(P54)-(MIN(M54,N($E$8))+MIN(N54,N($E$9))+MIN(O54,N($E$10))))) -> 240 | R54: =MAX(0,MIN(M54,$C$14-(P54+Q54)-(MIN(N54,N($E$9))+MIN(O54,N($E$10))))) -> 160 | S54: =MAX(0,MIN(N54,$C$14-(P54+Q54+R54)-(MIN(O54,N($E$10))))) -> 0 | T54: =MAX(0,MIN(O54,$C$14-(P54+Q54+R54+S54)-(0))) -> 0 | U54: =ROUND(K54-P54,2) -> 279.8 | V54: =ROUND(L54-Q54,2) -> 5579 | W54: =ROUND(M54-R54,2) -> 13067.46 | X54: =ROUND(N54-S54,2) -> 0 | Y54: =ROUND(O54-T54,2) -> 0 | Z54: =SUM(U54:Y54) -> 18926.26
J55: =EDATE($C$13,14) -> 46813 | K55: =U54*(1+N($D$6)/12) -> 285.13952 | L55: =V54*(1+N($D$7)/12) -> 5609.2196 | M55: =W54*(1+N($D$8)/12) -> 13121.908 | N55: =X54*(1+N($D$9)/12) -> 0 | O55: =Y54*(1+N($D$10)/12) -> 0 | P55: =MAX(0,MIN(K55,$C$14-(0)-(MIN(L55,N($E$7))+MIN(M55,N($E$8))+MIN(N55,N($E$9))+MIN(O55,N($E$10))))) -> 245 | Q55: =MAX(0,MIN(L55,$C$14-(P55)-(MIN(M55,N($E$8))+MIN(N55,N($E$9))+MIN(O55,N($E$10))))) -> 240 | R55: =MAX(0,MIN(M55,$C$14-(P55+Q55)-(MIN(N55,N($E$9))+MIN(O55,N($E$10))))) -> 160 | S55: =MAX(0,MIN(N55,$C$14-(P55+Q55+R55)-(MIN(O55,N($E$10))))) -> 0 | T55: =MAX(0,MIN(O55,$C$14-(P55+Q55+R55+S55)-(0))) -> 0 | U55: =ROUND(K55-P55,2) -> 40.14 | V55: =ROUND(L55-Q55,2) -> 5369.22 | W55: =ROUND(M55-R55,2) -> 12961.91 | X55: =ROUND(N55-S55,2) -> 0 | Y55: =ROUND(O55-T55,2) -> 0 | Z55: =SUM(U55:Y55) -> 18371.27
J56: =EDATE($C$13,15) -> 46844 | K56: =U55*(1+N($D$6)/12) -> 40.906005 | L56: =V55*(1+N($D$7)/12) -> 5398.3033 | M56: =W55*(1+N($D$8)/12) -> 13015.918 | N56: =X55*(1+N($D$9)/12) -> 0 | O56: =Y55*(1+N($D$10)/12) -> 0 | P56: =MAX(0,MIN(K56,$C$14-(0)-(MIN(L56,N($E$7))+MIN(M56,N($E$8))+MIN(N56,N($E$9))+MIN(O56,N($E$10))))) -> 40.906005 | Q56: =MAX(0,MIN(L56,$C$14-(P56)-(MIN(M56,N($E$8))+MIN(N56,N($E$9))+MIN(O56,N($E$10))))) -> 444.094 | R56: =MAX(0,MIN(M56,$C$14-(P56+Q56)-(MIN(N56,N($E$9))+MIN(O56,N($E$10))))) -> 160 | S56: =MAX(0,MIN(N56,$C$14-(P56+Q56+R56)-(MIN(O56,N($E$10))))) -> 0 | T56: =MAX(0,MIN(O56,$C$14-(P56+Q56+R56+S56)-(0))) -> 0 | U56: =ROUND(K56-P56,2) -> 0 | V56: =ROUND(L56-Q56,2) -> 4954.21 | W56: =ROUND(M56-R56,2) -> 12855.92 | X56: =ROUND(N56-S56,2) -> 0 | Y56: =ROUND(O56-T56,2) -> 0 | Z56: =SUM(U56:Y56) -> 17810.13
J57: =EDATE($C$13,16) -> 46874 | K57: =U56*(1+N($D$6)/12) -> 0 | L57: =V56*(1+N($D$7)/12) -> 4981.0453 | M57: =W56*(1+N($D$8)/12) -> 12909.486 | N57: =X56*(1+N($D$9)/12) -> 0 | O57: =Y56*(1+N($D$10)/12) -> 0 | P57: =MAX(0,MIN(K57,$C$14-(0)-(MIN(L57,N($E$7))+MIN(M57,N($E$8))+MIN(N57,N($E$9))+MIN(O57,N($E$10))))) -> 0 | Q57: =MAX(0,MIN(L57,$C$14-(P57)-(MIN(M57,N($E$8))+MIN(N57,N($E$9))+MIN(O57,N($E$10))))) -> 485 | R57: =MAX(0,MIN(M57,$C$14-(P57+Q57)-(MIN(N57,N($E$9))+MIN(O57,N($E$10))))) -> 160 | S57: =MAX(0,MIN(N57,$C$14-(P57+Q57+R57)-(MIN(O57,N($E$10))))) -> 0 | T57: =MAX(0,MIN(O57,$C$14-(P57+Q57+R57+S57)-(0))) -> 0 | U57: =ROUND(K57-P57,2) -> 0 | V57: =ROUND(L57-Q57,2) -> 4496.05 | W57: =ROUND(M57-R57,2) -> 12749.49 | X57: =ROUND(N57-S57,2) -> 0 | Y57: =ROUND(O57-T57,2) -> 0 | Z57: =SUM(U57:Y57) -> 17245.54
J58: =EDATE($C$13,17) -> 46905 | K58: =U57*(1+N($D$6)/12) -> 0 | L58: =V57*(1+N($D$7)/12) -> 4520.4036 | M58: =W57*(1+N($D$8)/12) -> 12802.613 | N58: =X57*(1+N($D$9)/12) -> 0 | O58: =Y57*(1+N($D$10)/12) -> 0 | P58: =MAX(0,MIN(K58,$C$14-(0)-(MIN(L58,N($E$7))+MIN(M58,N($E$8))+MIN(N58,N($E$9))+MIN(O58,N($E$10))))) -> 0 | Q58: =MAX(0,MIN(L58,$C$14-(P58)-(MIN(M58,N($E$8))+MIN(N58,N($E$9))+MIN(O58,N($E$10))))) -> 485 | R58: =MAX(0,MIN(M58,$C$14-(P58+Q58)-(MIN(N58,N($E$9))+MIN(O58,N($E$10))))) -> 160 | S58: =MAX(0,MIN(N58,$C$14-(P58+Q58+R58)-(MIN(O58,N($E$10))))) -> 0 | T58: =MAX(0,MIN(O58,$C$14-(P58+Q58+R58+S58)-(0))) -> 0 | U58: =ROUND(K58-P58,2) -> 0 | V58: =ROUND(L58-Q58,2) -> 4035.4 | W58: =ROUND(M58-R58,2) -> 12642.61 | X58: =ROUND(N58-S58,2) -> 0 | Y58: =ROUND(O58-T58,2) -> 0 | Z58: =SUM(U58:Y58) -> 16678.01
J59: =EDATE($C$13,18) -> 46935 | K59: =U58*(1+N($D$6)/12) -> 0 | L59: =V58*(1+N($D$7)/12) -> 4057.2584 | M59: =W58*(1+N($D$8)/12) -> 12695.288 | N59: =X58*(1+N($D$9)/12) -> 0 | O59: =Y58*(1+N($D$10)/12) -> 0 | P59: =MAX(0,MIN(K59,$C$14-(0)-(MIN(L59,N($E$7))+MIN(M59,N($E$8))+MIN(N59,N($E$9))+MIN(O59,N($E$10))))) -> 0 | Q59: =MAX(0,MIN(L59,$C$14-(P59)-(MIN(M59,N($E$8))+MIN(N59,N($E$9))+MIN(O59,N($E$10))))) -> 485 | R59: =MAX(0,MIN(M59,$C$14-(P59+Q59)-(MIN(N59,N($E$9))+MIN(O59,N($E$10))))) -> 160 | S59: =MAX(0,MIN(N59,$C$14-(P59+Q59+R59)-(MIN(O59,N($E$10))))) -> 0 | T59: =MAX(0,MIN(O59,$C$14-(P59+Q59+R59+S59)-(0))) -> 0 | U59: =ROUND(K59-P59,2) -> 0 | V59: =ROUND(L59-Q59,2) -> 3572.26 | W59: =ROUND(M59-R59,2) -> 12535.29 | X59: =ROUND(N59-S59,2) -> 0 | Y59: =ROUND(O59-T59,2) -> 0 | Z59: =SUM(U59:Y59) -> 16107.55
J60: =EDATE($C$13,19) -> 46966 | K60: =U59*(1+N($D$6)/12) -> 0 | L60: =V59*(1+N($D$7)/12) -> 3591.6097 | M60: =W59*(1+N($D$8)/12) -> 12587.52 | N60: =X59*(1+N($D$9)/12) -> 0 | O60: =Y59*(1+N($D$10)/12) -> 0 | P60: =MAX(0,MIN(K60,$C$14-(0)-(MIN(L60,N($E$7))+MIN(M60,N($E$8))+MIN(N60,N($E$9))+MIN(O60,N($E$10))))) -> 0 | Q60: =MAX(0,MIN(L60,$C$14-(P60)-(MIN(M60,N($E$8))+MIN(N60,N($E$9))+MIN(O60,N($E$10))))) -> 485 | R60: =MAX(0,MIN(M60,$C$14-(P60+Q60)-(MIN(N60,N($E$9))+MIN(O60,N($E$10))))) -> 160 | S60: =MAX(0,MIN(N60,$C$14-(P60+Q60+R60)-(MIN(O60,N($E$10))))) -> 0 | T60: =MAX(0,MIN(O60,$C$14-(P60+Q60+R60+S60)-(0))) -> 0 | U60: =ROUND(K60-P60,2) -> 0 | V60: =ROUND(L60-Q60,2) -> 3106.61 | W60: =ROUND(M60-R60,2) -> 12427.52 | X60: =ROUND(N60-S60,2) -> 0 | Y60: =ROUND(O60-T60,2) -> 0 | Z60: =SUM(U60:Y60) -> 15534.13
J61: =EDATE($C$13,20) -> 46997 | K61: =U60*(1+N($D$6)/12) -> 0 | L61: =V60*(1+N($D$7)/12) -> 3123.4375 | M61: =W60*(1+N($D$8)/12) -> 12479.301 | N61: =X60*(1+N($D$9)/12) -> 0 | O61: =Y60*(1+N($D$10)/12) -> 0 | P61: =MAX(0,MIN(K61,$C$14-(0)-(MIN(L61,N($E$7))+MIN(M61,N($E$8))+MIN(N61,N($E$9))+MIN(O61,N($E$10))))) -> 0 | Q61: =MAX(0,MIN(L61,$C$14-(P61)-(MIN(M61,N($E$8))+MIN(N61,N($E$9))+MIN(O61,N($E$10))))) -> 485 | R61: =MAX(0,MIN(M61,$C$14-(P61+Q61)-(MIN(N61,N($E$9))+MIN(O61,N($E$10))))) -> 160 | S61: =MAX(0,MIN(N61,$C$14-(P61+Q61+R61)-(MIN(O61,N($E$10))))) -> 0 | T61: =MAX(0,MIN(O61,$C$14-(P61+Q61+R61+S61)-(0))) -> 0 | U61: =ROUND(K61-P61,2) -> 0 | V61: =ROUND(L61-Q61,2) -> 2638.44 | W61: =ROUND(M61-R61,2) -> 12319.3 | X61: =ROUND(N61-S61,2) -> 0 | Y61: =ROUND(O61-T61,2) -> 0 | Z61: =SUM(U61:Y61) -> 14957.74
J62: =EDATE($C$13,21) -> 47027 | K62: =U61*(1+N($D$6)/12) -> 0 | L62: =V61*(1+N($D$7)/12) -> 2652.7315 | M62: =W61*(1+N($D$8)/12) -> 12370.63 | N62: =X61*(1+N($D$9)/12) -> 0 | O62: =Y61*(1+N($D$10)/12) -> 0 | P62: =MAX(0,MIN(K62,$C$14-(0)-(MIN(L62,N($E$7))+MIN(M62,N($E$8))+MIN(N62,N($E$9))+MIN(O62,N($E$10))))) -> 0 | Q62: =MAX(0,MIN(L62,$C$14-(P62)-(MIN(M62,N($E$8))+MIN(N62,N($E$9))+MIN(O62,N($E$10))))) -> 485 | R62: =MAX(0,MIN(M62,$C$14-(P62+Q62)-(MIN(N62,N($E$9))+MIN(O62,N($E$10))))) -> 160 | S62: =MAX(0,MIN(N62,$C$14-(P62+Q62+R62)-(MIN(O62,N($E$10))))) -> 0 | T62: =MAX(0,MIN(O62,$C$14-(P62+Q62+R62+S62)-(0))) -> 0 | U62: =ROUND(K62-P62,2) -> 0 | V62: =ROUND(L62-Q62,2) -> 2167.73 | W62: =ROUND(M62-R62,2) -> 12210.63 | X62: =ROUND(N62-S62,2) -> 0 | Y62: =ROUND(O62-T62,2) -> 0 | Z62: =SUM(U62:Y62) -> 14378.36
J63: =EDATE($C$13,22) -> 47058 | K63: =U62*(1+N($D$6)/12) -> 0 | L63: =V62*(1+N($D$7)/12) -> 2179.4719 | M63: =W62*(1+N($D$8)/12) -> 12261.508 | N63: =X62*(1+N($D$9)/12) -> 0 | O63: =Y62*(1+N($D$10)/12) -> 0 | P63: =MAX(0,MIN(K63,$C$14-(0)-(MIN(L63,N($E$7))+MIN(M63,N($E$8))+MIN(N63,N($E$9))+MIN(O63,N($E$10))))) -> 0 | Q63: =MAX(0,MIN(L63,$C$14-(P63)-(MIN(M63,N($E$8))+MIN(N63,N($E$9))+MIN(O63,N($E$10))))) -> 485 | R63: =MAX(0,MIN(M63,$C$14-(P63+Q63)-(MIN(N63,N($E$9))+MIN(O63,N($E$10))))) -> 160 | S63: =MAX(0,MIN(N63,$C$14-(P63+Q63+R63)-(MIN(O63,N($E$10))))) -> 0 | T63: =MAX(0,MIN(O63,$C$14-(P63+Q63+R63+S63)-(0))) -> 0 | U63: =ROUND(K63-P63,2) -> 0 | V63: =ROUND(L63-Q63,2) -> 1694.47 | W63: =ROUND(M63-R63,2) -> 12101.51 | X63: =ROUND(N63-S63,2) -> 0 | Y63: =ROUND(O63-T63,2) -> 0 | Z63: =SUM(U63:Y63) -> 13795.98
J64: =EDATE($C$13,23) -> 47088 | K64: =U63*(1+N($D$6)/12) -> 0 | L64: =V63*(1+N($D$7)/12) -> 1703.6484 | M64: =W63*(1+N($D$8)/12) -> 12151.933 | N64: =X63*(1+N($D$9)/12) -> 0 | O64: =Y63*(1+N($D$10)/12) -> 0 | P64: =MAX(0,MIN(K64,$C$14-(0)-(MIN(L64,N($E$7))+MIN(M64,N($E$8))+MIN(N64,N($E$9))+MIN(O64,N($E$10))))) -> 0 | Q64: =MAX(0,MIN(L64,$C$14-(P64)-(MIN(M64,N($E$8))+MIN(N64,N($E$9))+MIN(O64,N($E$10))))) -> 485 | R64: =MAX(0,MIN(M64,$C$14-(P64+Q64)-(MIN(N64,N($E$9))+MIN(O64,N($E$10))))) -> 160 | S64: =MAX(0,MIN(N64,$C$14-(P64+Q64+R64)-(MIN(O64,N($E$10))))) -> 0 | T64: =MAX(0,MIN(O64,$C$14-(P64+Q64+R64+S64)-(0))) -> 0 | U64: =ROUND(K64-P64,2) -> 0 | V64: =ROUND(L64-Q64,2) -> 1218.65 | W64: =ROUND(M64-R64,2) -> 11991.93 | X64: =ROUND(N64-S64,2) -> 0 | Y64: =ROUND(O64-T64,2) -> 0 | Z64: =SUM(U64:Y64) -> 13210.58
J65: =EDATE($C$13,24) -> 47119 | K65: =U64*(1+N($D$6)/12) -> 0 | L65: =V64*(1+N($D$7)/12) -> 1225.251 | M65: =W64*(1+N($D$8)/12) -> 12041.896 | N65: =X64*(1+N($D$9)/12) -> 0 | O65: =Y64*(1+N($D$10)/12) -> 0 | P65: =MAX(0,MIN(K65,$C$14-(0)-(MIN(L65,N($E$7))+MIN(M65,N($E$8))+MIN(N65,N($E$9))+MIN(O65,N($E$10))))) -> 0 | Q65: =MAX(0,MIN(L65,$C$14-(P65)-(MIN(M65,N($E$8))+MIN(N65,N($E$9))+MIN(O65,N($E$10))))) -> 485 | R65: =MAX(0,MIN(M65,$C$14-(P65+Q65)-(MIN(N65,N($E$9))+MIN(O65,N($E$10))))) -> 160 | S65: =MAX(0,MIN(N65,$C$14-(P65+Q65+R65)-(MIN(O65,N($E$10))))) -> 0 | T65: =MAX(0,MIN(O65,$C$14-(P65+Q65+R65+S65)-(0))) -> 0 | U65: =ROUND(K65-P65,2) -> 0 | V65: =ROUND(L65-Q65,2) -> 740.25 | W65: =ROUND(M65-R65,2) -> 11881.9 | X65: =ROUND(N65-S65,2) -> 0 | Y65: =ROUND(O65-T65,2) -> 0 | Z65: =SUM(U65:Y65) -> 12622.15
J66: =EDATE($C$13,25) -> 47150 | K66: =U65*(1+N($D$6)/12) -> 0 | L66: =V65*(1+N($D$7)/12) -> 744.25969 | M66: =W65*(1+N($D$8)/12) -> 11931.408 | N66: =X65*(1+N($D$9)/12) -> 0 | O66: =Y65*(1+N($D$10)/12) -> 0 | P66: =MAX(0,MIN(K66,$C$14-(0)-(MIN(L66,N($E$7))+MIN(M66,N($E$8))+MIN(N66,N($E$9))+MIN(O66,N($E$10))))) -> 0 | Q66: =MAX(0,MIN(L66,$C$14-(P66)-(MIN(M66,N($E$8))+MIN(N66,N($E$9))+MIN(O66,N($E$10))))) -> 485 | R66: =MAX(0,MIN(M66,$C$14-(P66+Q66)-(MIN(N66,N($E$9))+MIN(O66,N($E$10))))) -> 160 | S66: =MAX(0,MIN(N66,$C$14-(P66+Q66+R66)-(MIN(O66,N($E$10))))) -> 0 | T66: =MAX(0,MIN(O66,$C$14-(P66+Q66+R66+S66)-(0))) -> 0 | U66: =ROUND(K66-P66,2) -> 0 | V66: =ROUND(L66-Q66,2) -> 259.26 | W66: =ROUND(M66-R66,2) -> 11771.41 | X66: =ROUND(N66-S66,2) -> 0 | Y66: =ROUND(O66-T66,2) -> 0 | Z66: =SUM(U66:Y66) -> 12030.67
...

Sheet Savings Goals
B2: Savings Goals
B3: Give every goal a date. Sorted works out the monthly amount.
B5: Goal | C5: Target | D5: Saved so far | E5: Target date | F5: Months left | G5: Save per month | H5: Progress
B6: Emergency fund (3 months) | C6: 9000 | D6: 2400 | E6: =EDATE(TODAY(),12) -> 46661 | F6: =IF(OR(B6="",E6=""),"",MAX(1,(YEAR(E6)-YEAR(TODAY()))*12+MONTH(E6)-MONTH(TODAY()))) -> 12 | G6: =IF(F6="","",MAX(0,(C6-D6)/F6)) -> 550 | H6: =IF(N(C6)=0,"",MIN(1,D6/C6)) -> 0.26666667
B7: Summer holiday | C7: 2500 | D7: 600 | E7: =EDATE(TODAY(),7) -> 46508 | F7: =IF(OR(B7="",E7=""),"",MAX(1,(YEAR(E7)-YEAR(TODAY()))*12+MONTH(E7)-MONTH(TODAY()))) -> 7 | G7: =IF(F7="","",MAX(0,(C7-D7)/F7)) -> 271.42857 | H7: =IF(N(C7)=0,"",MIN(1,D7/C7)) -> 0.24
B8: New laptop | C8: 1400 | D8: 350 | E8: =EDATE(TODAY(),5) -> 46447 | F8: =IF(OR(B8="",E8=""),"",MAX(1,(YEAR(E8)-YEAR(TODAY()))*12+MONTH(E8)-MONTH(TODAY()))) -> 5 | G8: =IF(F8="","",MAX(0,(C8-D8)/F8)) -> 210 | H8: =IF(N(C8)=0,"",MIN(1,D8/C8)) -> 0.25
B9: House deposit | C9: 30000 | D9: 4200 | E9: =EDATE(TODAY(),36) -> 47392 | F9: =IF(OR(B9="",E9=""),"",MAX(1,(YEAR(E9)-YEAR(TODAY()))*12+MONTH(E9)-MONTH(TODAY()))) -> 36 | G9: =IF(F9="","",MAX(0,(C9-D9)/F9)) -> 716.66667 | H9: =IF(N(C9)=0,"",MIN(1,D9/C9)) -> 0.14
F10: =IF(OR(B10="",E10=""),"",MAX(1,(YEAR(E10)-YEAR(TODAY()))*12+MONTH(E10)-MONTH(TODAY()))) | G10: =IF(F10="","",MAX(0,(C10-D10)/F10)) | H10: =IF(N(C10)=0,"",MIN(1,D10/C10))
F11: =IF(OR(B11="",E11=""),"",MAX(1,(YEAR(E11)-YEAR(TODAY()))*12+MONTH(E11)-MONTH(TODAY()))) | G11: =IF(F11="","",MAX(0,(C11-D11)/F11)) | H11: =IF(N(C11)=0,"",MIN(1,D11/C11))
F12: =IF(OR(B12="",E12=""),"",MAX(1,(YEAR(E12)-YEAR(TODAY()))*12+MONTH(E12)-MONTH(TODAY()))) | G12: =IF(F12="","",MAX(0,(C12-D12)/F12)) | H12: =IF(N(C12)=0,"",MIN(1,D12/C12))
F13: =IF(OR(B13="",E13=""),"",MAX(1,(YEAR(E13)-YEAR(TODAY()))*12+MONTH(E13)-MONTH(TODAY()))) | G13: =IF(F13="","",MAX(0,(C13-D13)/F13)) | H13: =IF(N(C13)=0,"",MIN(1,D13/C13))
F14: =IF(OR(B14="",E14=""),"",MAX(1,(YEAR(E14)-YEAR(TODAY()))*12+MONTH(E14)-MONTH(TODAY()))) | G14: =IF(F14="","",MAX(0,(C14-D14)/F14)) | H14: =IF(N(C14)=0,"",MIN(1,D14/C14))
F15: =IF(OR(B15="",E15=""),"",MAX(1,(YEAR(E15)-YEAR(TODAY()))*12+MONTH(E15)-MONTH(TODAY()))) | G15: =IF(F15="","",MAX(0,(C15-D15)/F15)) | H15: =IF(N(C15)=0,"",MIN(1,D15/C15))
F16: =IF(OR(B16="",E16=""),"",MAX(1,(YEAR(E16)-YEAR(TODAY()))*12+MONTH(E16)-MONTH(TODAY()))) | G16: =IF(F16="","",MAX(0,(C16-D16)/F16)) | H16: =IF(N(C16)=0,"",MIN(1,D16/C16))
F17: =IF(OR(B17="",E17=""),"",MAX(1,(YEAR(E17)-YEAR(TODAY()))*12+MONTH(E17)-MONTH(TODAY()))) | G17: =IF(F17="","",MAX(0,(C17-D17)/F17)) | H17: =IF(N(C17)=0,"",MIN(1,D17/C17))
B19: Total to set aside each month | G19: =SUM(G6:G17) -> 1748.0952
B20: Compare this with your Savings budget on the Setup tab.
